Workbook
Name Exp_Item: 'Ext. Inputs'!$B$7:$B$14
Name Exp_Dev: 'Ext. Inputs'!$C$7:$C$14
Name Exp_Emg: 'Ext. Inputs'!$D$7:$D$14
Name Lvl_Bld: 'Ext. Inputs'!$C$19
Name Lvl_Cnt: 'Ext. Inputs'!$C$20
Name Lvl_MotRen: 'Ext. Inputs'!$C$21
Name Lvl_MotNB: 'Ext. Inputs'!$C$22
Name Lvl_MotNB2: 'Ext. Inputs'!$C$23
Name SI_Thr_Cnt: 'Ext. Inputs'!$C$24
Name SI_Thr_Bld: 'Ext. Inputs'!$C$25
Name SI_Div: 'Ext. Inputs'!$C$26
Name XGB_Base: 'Ext. Inputs'!$C$27
Name XGB_Trend: 'Ext. Inputs'!$C$28
Name Py_ID: 'Ext. Inputs'!$B$32:$B$51
Name Py_Small: 'Ext. Inputs'!$D$32:$D$51
Name Py_Large: 'Ext. Inputs'!$E$32:$E$51
Name Py_AsIs: 'Ext. Inputs'!$F$32:$F$51
Name Py_Final: 'Ext. Inputs'!$G$32:$G$51
Name Sw_Market: 'Int. Inputs'!$C$6
Name In_CompSite: 'Int. Inputs'!$C$7
Name Sw_CatBase: 'Int. Inputs'!$C$8
Name In_CatShare_Bld: 'Int. Inputs'!$C$9
Name In_CatShare_Cnt: 'Int. Inputs'!$C$10
Name Pol_ID: 'Int. Inputs'!$B$16:$B$35
Name Pol_Head: 'Int. Inputs'!$B$14:$BT$14
Name Pol_Data: 'Int. Inputs'!$B$16:$BT$35
Name Terms_Key: 'Lookups'!$B$7:$B$8106
Name Terms_Kind: 'Lookups'!$F$7:$F$8106
Name Terms_Lower: 'Lookups'!$I$7:$I$8106
Name Terms_Contrib: 'Lookups'!$K$7:$K$8106
Name Terms_LCT: 'Lookups'!$N$7:$N$8106
Name Remap_Key: 'Lookups'!$P$7:$P$8
Name Remap_To: 'Lookups'!$Q$7:$Q$8
Name Con_Raw: 'Lookups'!$P$12:$P$15
Name Con_Model: 'Lookups'!$Q$12:$Q$15
Name YB_Rating: 'Lookups'!$P$19:$P$26
Name YB_Fill: 'Lookups'!$Q$19:$Q$26
Name Fmt_LCT: 'Lookups'!$P$30:$P$40
Name Fmt_Str: 'Lookups'!$Q$30:$Q$40
Name Node_Key: 'Lookups Trees'!$B$7:$B$2583
Name Node_Kind: 'Lookups Trees'!$E$7:$E$2583
Name Node_Pos: 'Lookups Trees'!$F$7:$F$2583
Name Node_Thr: 'Lookups Trees'!$H$7:$H$2583
Name Node_RCodes: 'Lookups Trees'!$I$7:$I$2583
Name Node_Miss: 'Lookups Trees'!$K$7:$K$2583
Name Node_Left: 'Lookups Trees'!$L$7:$L$2583
Name Node_Right: 'Lookups Trees'!$M$7:$M$2583
Name Node_Leaf: 'Lookups Trees'!$N$7:$N$2583
Name Feat_Key: 'Lookups Trees'!$P$7:$P$224
Name Feat_Code: 'Lookups Trees'!$T$7:$T$224
Name RM_ID: 'Rating Motor'!$B$10:$B$16
Name RM_Final: 'Rating Motor'!$BP$10:$BP$16
Name RC_ID: 'Rating Contents'!$B$10:$B$15
Name RC_Final: 'Rating Contents'!$BQ$10:$BQ$15
Name RB_ID: 'Rating Buildings Trees'!$BZ$10:$BZ$16
Name RB_Final: 'Rating Buildings Trees'!$CH$10:$CH$16
Name OP_ID: 'Office Premium'!$B$17:$B$36
Name OP_Line: 'Office Premium'!$C$17:$C$36
Name OP_NB: 'Office Premium'!$E$17:$E$36
Name OP_Channel: 'Office Premium'!$D$17:$D$36

Sheet Audit
B2: IAA Hackathon 2026, Week 2: rating model replica
B4: Purpose | C4: Excel replica of the Week 2 submitted model (C0 with segment levels) for the 20 reference policies, and the office premium build-up. Doubles as an independent check of the Python model.
B5: Owner | C5: Cian Herrera Quinn
B6: Team | C6: Alan McDonagh, Bridget MacDonnell, Gerard Murphy, Cian Herrera Quinn
B7: Source | C7: Gerard's Excel export (contents/gerard-week2-emerging, export/excel, run f3548525, commit a56b201) and the emerging data
B8: Last updated | C8: 46324
B9: Version | C9: v0.4 (draft)
B11: Checks summary (0 = pass)
B12: Sheet | C12: Check | D12: Value | E12: Result
B13: Rating Motor | C13: motor: policies where Excel differs from Python by more than 1e-9 | D13: =ROUND('Rating Motor'!BR5,2) | E13: =IF(D13=0,"Pass","Fail")
B14: Rating Motor | C14: motor: rating keys not found in the Lookups | D14: =ROUND('Rating Motor'!BS5,2) | E14: =IF(D14=0,"Pass","Fail")
B15: Rating Buildings | C15: buildings large claims: policies where Excel differs from Python by more than 1e-9 | D15: =ROUND('Rating Buildings'!AS5,2) | E15: =IF(D15=0,"Pass","Fail")
B16: Rating Buildings | C16: buildings: rating keys not found in the Lookups | D16: =ROUND('Rating Buildings'!AT5,2) | E16: =IF(D16=0,"Pass","Fail")
B17: Rating Contents | C17: contents: policies where Excel differs from Python by more than 1e-9 | D17: =ROUND('Rating Contents'!BS5,2) | E17: =IF(D17=0,"Pass","Fail")
B18: Rating Contents | C18: contents: rating keys not found in the Lookups | D18: =ROUND('Rating Contents'!BT5,2) | E18: =IF(D18=0,"Pass","Fail")
B19: Rating Buildings Trees | C19: buildings small claims: policies where Excel differs from XGBoost by more than 1e-5 | D19: =ROUND('Rating Buildings Trees'!CJ5,2) | E19: =IF(D19=0,"Pass","Fail")
B20: Rating Buildings Trees | C20: buildings final: policies where Excel differs from Python by more than 1e-5 | D20: =ROUND('Rating Buildings Trees'!CL5,2) | E20: =IF(D20=0,"Pass","Fail")
B21: Rating Buildings Trees | C21: buildings trees: category inputs with no code (scored as missing) | D21: =ROUND('Rating Buildings Trees'!CM5,2) | E21: =IF(D21=0,"Pass","Fail")
B22: Rating Buildings Trees | C22: buildings trees: walks that did not end at a leaf | D22: =ROUND('Rating Buildings Trees'!CN5,2) | E22: =IF(D22=0,"Pass","Fail")
B23: Office Premium | C23: Office premium components add back to the office premium | D23: =ROUND('Office Premium'!X14,2) | E23: =IF(D23=0,"Pass","Fail")
C24: Workbook total | D24: =SUM(D13:D23) | E24: =IF(D24=0,"Pass","Fail")
B26: Open items (green cells: waiting for data)
B27: Sheet | C27: Item | D27: Cell
B28: None | C28: Every input is present; no cell is waiting for data.
B30: Cell-fill legend
B31: Type | C31: Fill | D31: Example
B32: Variable input (Int. Inputs) | C32: #CCFFCC | D32: Example
B33: Static input (Ext. Inputs) | C33: #CCFFFF | D33: Example
B34: Formula: internal link, copyable | C34: #FFFFCC | D34: Example
B35: Formula: internal link, distinct | C35: #FFFF99 | D35: Example
B36: Formula: external link, copyable | C36: #FCE4D6 | D36: Example
B37: Formula: external link, distinct | C37: #F8CBAD | D37: Example
B38: Check / control (0 = pass) | C38: #FFFF00 | D38: Example
B39: Temporarily highlighted (open item) | C39: #00FF00 | D39: Example
B40: Table heading | C40: #D9D9D9 | D40: Example
B41: Author notes (blue font, no fill) | C41: text #0000FF | D41: Example
B43: Tab colours
B44: Grey: system / master / Audit | C44: #D9D9D9
B45: Blue: static inputs | C45: #CCFFFF
B46: Green: variable inputs | C46: #CCFFCC
...

Sheet Ext. Inputs
B2: Ext. Inputs: static inputs delivered with the data or taken from the model export
B3: Blue cells are delivered values: change them only if the source changes. Sources are noted beside each block.
B5: Expense assumptions (expenses.parquet)
B6: Item | C6: Developed | D6: Emerging | E6: Unit
B7: fixed_expense_per_policy | C7: 45 | D7: 85 | E7: CU
B8: variable_expense | C8: 0.12 | D8: 0.15 | E8: share of premium
B9: commission_direct | C9: 0 | D9: 0 | E9: share of premium
B10: commission_comparison_site | C10: 0.1 | E10: share of premium
B11: commission_broker | C11: 0.15 | D11: 0.2 | E11: share of premium
B12: premium_tax | C12: 0.12 | D12: 0.08 | E12: share of premium
B13: cat_reinsurance | C13: 0.06 | D13: 0.12 | E13: share of property risk premium
B14: target_profit_margin | C14: 0.05 | D14: 0.08 | E14: share of premium
B15: The emerging comparison-site commission is blank in the delivered file; Int. Inputs sets what stands in for it.
B17: Model scalars (export scalars.csv, run f3548525)
B18: Item | C18: Value | D18: Note
B19: Level step 1: buildings | C19: 0.95748473 | D19: halfway scale, all buildings rows
B20: Level step 1: contents | C20: 0.86574939 | D20: halfway scale, all contents rows
B21: Level step 1: motor renewals | C21: 0.8614202 | D21: halfway scale
B22: Level step 1: motor new business | C22: 0.9807983 | D22: halfway scale, then step 2
B23: Level step 2: motor new business | C23: 1.05 | D23: x1.05, then divided by its step 1 (final file A31 write4.py)
B24: Sum insured fix D-02: contents threshold | C24: 1000000 | D24: at or above: divide by the divisor
B25: Sum insured fix D-02: buildings threshold | C25: 10000000 | D25: at or above: divide by the divisor
B26: Sum insured fix D-02: divisor | C26: 1000
B27: Buildings XGBoost base rate | C27: 350.18118 | D27: in the offset: ln(base rate) is added to the margin
B28: Buildings small-claim trend multiplier 2025 | C28: 1.1203255 | D28: in the offset: ln(multiplier) is added to the margin
B30: Python results for the reference policies (check values; buildings small claims are an input)
B31: Policy row | C31: Line | D31: Small claim | E31: Large claim | F31: As is | G31: Final
B32: M00118569 | C32: motor | D32: 681.55096 | E32: 69.689487 | F32: 751.24045 | G32: 647.1337
B33: M00129413 | C33: motor | D33: 213.04057 | E33: 13.360613 | F33: 226.40119 | G33: 237.72125
B34: M00153851 | C34: motor | D34: 328.14408 | E34: 7.1410228 | F34: 335.28511 | G34: 352.04936
B35: M00161473 | C35: motor | D35: 1172.0059 | E35: 71.518074 | F35: 1243.524 | G35: 1305.7002
B36: M00167496 | C36: motor | D36: 539.20026 | E36: 75.519747 | F36: 614.72 | G36: 645.456
B37: M00176777 | C37: motor | D37: 834.38404 | E37: 39.971419 | F37: 874.35546 | G37: 918.07323
B38: M00185311 | C38: motor | D38: 1024.3208 | E38: 71.518074 | F38: 1095.8388 | G38: 1150.6308
B39: B00215707 | C39: buildings | D39: 246.71988 | E39: 51.962513 | F39: 298.68239 | G39: 285.98383
B40: B00215809 | C40: buildings | D40: 456.50452 | E40: 113.28205 | F40: 569.78657 | G40: 545.56193
B41: B00217584 | C41: buildings | D41: 1266.0942 | E41: 587.67961 | F41: 1853.7738 | G41: 1774.9601
B42: B00218282 | C42: buildings | D42: 280.72574 | E42: 29.453764 | F42: 310.1795 | G42: 296.99214
B43: B00223369 | C43: buildings | D43: 368.43826 | E43: 46.044228 | F43: 414.48249 | G43: 396.86065
... B51: C00314425 | C51: contents | D51: 7.1380567 | E51: 0 | F51: 7.1380567 | G51: 6.1797682
...

Sheet Int. Inputs
B2: Int. Inputs: switches and the 20 reference policies
B3: Green cells are yours to change. Edit a policy's details to re-quote it; every sheet to the right recalculates.
B5: Switch / assumption | C5: Value | D5: Note
B6: Expense basis (market column) | C6: emerging | D6: emerging or developed, from expenses.parquet
B7: Comparison-site commission if blank | C7: 0.1 | D7: The emerging rate is blank; Ger's office_premium.py uses the developed 10%. An assumption for the team
B8: Cat reinsurance base | C8: All property risk premium | D8: All property risk premium (Ger's office_premium.py) or Cat perils only (Bridget, discussion #171)
B9: Cat peril share: buildings | C9: 0.3498 | D9: Storm + flood share of emerging 2023-24 buildings claims cost (net incurred, excluding repudiated). Used only when the base is Cat perils only
B10: Cat peril share: contents | C10: 0.3041 | D10: Flood share of emerging 2023-24 contents claims cost (contents has no storm peril). Used only when the base is Cat perils only
B13: Reference policies (reference_policies.parquet, with customer, address and 2025 weather fields joined; blank = missing or not applicable)
B14: row_id | C14: line | D14: new_business | E14: channel | F14: period_start | G14: period_end | H14: exposure | I14: written_premium | J14: driver_age_band | K14: years_licensed | L14: ncb_years | M14: vehicle_value_group | N14: vehicle_age | O14: cover_type | P14: vehicle_use | Q14: voluntary_excess | R14: payment_method | S14: missed_payments_12m | T14: marketing_segment | U14: prior_claims_5y | V14: policyholder_age_band | W14: sum_insured | X14: construction_type | Y14: tenure | Z14: security_level | AA14: high_value_items | AB14: accidental_damage_cover | AC14: bicycle_cover | AD14: works_from_home | AE14: lodgers | AF14: urban_density | AG14: flood_zone | AH14: elevation_m | AI14: distance_to_river_km | AJ14: soil_type | AK14: property_type | AL14: year_built | AM14: energy_rating | AN14: dry_summer_index | AO14: rainfall_mm | AP14: days_unoccupied | AQ14: renewal_count | AR14: days_quote_to_inception | AS14: discount_applied | AT14: occupancy | AU14: smoke_alarms | AV14: mortgage | AW14: household_size | AX14: licence_points | AY14: years_at_address | AZ14: customer_since_year | BA14: marital_status | BB14: email_domain | BC14: marketing_consent | BD14: document_preference | BE14: previous_insurer | BF14: campaign_code | BG14: branch_id | BH14: bedrooms | BI14: roof_type | BJ14: basement | BK14: trees_within_5m | BL14: listed_building | BM14: solar_panels | BN14: hail_days | BO14: wind_exposure_index | BP14: freezing_days | BQ14: wildfire_index | BR14: mean_temperature_c | BS14: customer_id | BT14: address_id
B15: Policy row | C15: Line | D15: New business | E15: Channel | F15: Period start | G15: Period end | H15: Exposure (reference file) | I15: Written premium (CU) | J15: Driver age band | K15: Years licensed | L15: NCB years | M15: Vehicle value group | N15: Vehicle age | O15: Cover type | P15: Vehicle use | Q15: Voluntary excess | R15: Payment method | S15: Missed payments 12m | T15: Marketing segment | U15: Prior claims 5y | V15: Policyholder age band | W15: Sum insured (raw) | X15: Construction code (raw) | Y15: Tenure | Z15: Security level | AA15: High-value items | AB15: Accidental damage cover | AC15: Bicycle cover | AD15: Works from home | AE15: Lodgers | AF15: Urban density | AG15: Flood zone | AH15: Elevation (m) | AI15: Distance to river (km) | AJ15: Soil type | AK15: Property type | AL15: Year built (raw) | AM15: Energy rating | AN15: Dry summer index 2025 | AO15: Rainfall 2025 (mm) | AP15: Days unoccupied | AQ15: Renewal count | AR15: Days quote to inception | AS15: Discount applied | AT15: Occupancy | AU15: Smoke alarms | AV15: Mortgage | AW15: Household size | AX15: Licence points | AY15: Years at address | AZ15: Customer since (year) | BA15: Marital status | BB15: Email domain | BC15: Marketing consent | BD15: Document preference | BE15: Previous insurer | BF15: Campaign code | BG15: Branch | BH15: Bedrooms | BI15: Roof type | BJ15: Basement | BK15: Trees within 5m | BL15: Listed building | BM15: Solar panels | BN15: Hail days 2025 | BO15: Wind exposure index 2025 | BP15: Freezing days 2025 | BQ15: Wildfire index 2025 | BR15: Mean temperature 2025 (C) | BS15: Customer | BT15: Address
B16: M00118569 | C16: motor | D16: false | E16: direct | F16: 45658 | G16: 46000 | H16: 0.9397 | I16: 1095.48 | J16: 17-24 | K16: 2 | L16: 1 | M16: 6 | N16: 11 | O16: third_party_fire_theft | P16: social | Q16: 0 | R16: monthly | S16: 0 | T16: young_mainstream | U16: 0 | AF16: suburban | AG16: 1 | AH16: 10.4 | AI16: 1.37 | AJ16: sand | AK16: terraced | AL16: 2016 | AN16: 0.754 | AO16: 1017 | AQ16: 4 | AR16: 16 | AS16: 0.05 | AW16: 2 | AX16: 0 | AY16: 4 | AZ16: 2021 | BA16: single | BB16: netbox | BC16: false | BD16: email | BE16: INS04 | BG16: 2 | BH16: 3 | BI16: pitched | BJ16: false | BK16: false | BL16: false | BM16: false | BN16: 7 | BO16: 5.7 | BP16: 52 | BQ16: 0.521 | BR16: 13.2 | BS16: 81575987 | BT16: A6924348
B17: M00129413 | C17: motor | D17: true | E17: broker | F17: 45902 | G17: 46022 | H17: 0.3315 | I17: 354.15 | J17: 25-34 | K17: 5 | L17: 5 | M17: 5 | O17: comprehensive | P17: social | Q17: 250 | R17: monthly | S17: 0 | T17: young_budget | U17: 1 | AF17: rural | AG17: 1 | AH17: 15.1 | AI17: 4.66 | AJ17: sand | AK17: detached | AL17: 1991 | AM17: B | AN17: 0.329 | AO17: 1071 | AQ17: 0 | AR17: 2 | AS17: 0 | AW17: 2 | AX17: 0 | AY17: 11 | AZ17: 2025 | BA17: married | BB17: netbox | BC17: false | BD17: email | BE17: INS17 | BF17: CMP09 | BG17: 9 | BH17: 4 | BI17: pitched | BJ17: false | BK17: false | BL17: false | BM17: false | BN17: 10 | BO17: 6.6 | BP17: 39 | BQ17: 0.39 | BR17: 11.5 | BS17: 05068935 | BT17: A0759646
B18: M00153851 | C18: motor | D18: true | E18: broker | F18: 45672 | G18: 46022 | H18: 0.9616 | I18: 414.72 | J18: 35-49 | K18: 29 | L18: 10 | M18: 9 | N18: 4 | O18: comprehensive | P18: commuting | Q18: 0 | R18: annual | S18: 0 | T18: midlife_affluent | U18: 0 | AF18: suburban | AG18: 1 | AH18: 11.8 | AJ18: loam | AK18: detached | AL18: 2012 | AM18: A | AN18: 0.925 | AO18: 1276 | AQ18: 0 | AR18: 18 | AS18: 0 | AW18: 5 | AX18: 0 | AY18: 2 | AZ18: 2025 | BA18: married | BB18: inboxly | BC18: false | BD18: email | BE18: INS26 | BF18: CMP13 | BG18: 5 | BH18: 4 | BI18: pitched | BJ18: false | BK18: false | BL18: false | BM18: false | BN18: 2 | BO18: 4.2 | BP18: 0 | BQ18: 0.69 | BR18: 18.8 | BS18: 72238013 | BT18: A9220498
B19: M00161473 | C19: motor | D19: true | E19: broker | F19: 45671 | G19: 46022 | H19: 0.9644 | I19: 1131.78 | J19: 17-24 | K19: 0 | L19: 0 | M19: 6 | N19: 15 | O19: third_party_fire_theft | P19: social | Q19: 250 | R19: monthly | S19: 0 | T19: young_mainstream | U19: 1 | AF19: rural | AG19: 1 | AH19: 15.2 | AI19: 6.2 | AJ19: clay | AK19: flat | AL19: 1956 | AM19: D | AN19: 0.507 | AO19: 1077 | AQ19: 0 | AR19: 24 | AS19: 0 | AW19: 2 | AX19: 0 | AY19: 2 | AZ19: 2025 | BA19: single | BB19: mailone | BC19: true | BD19: email | BE19: INS36 | BF19: CMP02 | BG19: 21 | BH19: 1 | BI19: pitched | BJ19: false | BK19: true | BL19: false | BM19: false | BN19: 24 | BO19: 7 | BP19: 23 | BQ19: 0.554 | BR19: 14.2 | BS19: 88632978 | BT19: A3687131
B20: M00167496 | C20: motor | D20: true | E20: broker | F20: 45664 | G20: 46022 | H20: 0.9836 | I20: 463.95 | J20: 25-34 | K20: 9 | L20: 6 | M20: 8 | N20: 11 | O20: comprehensive | P20: business | Q20: 250 | R20: monthly | S20: 0 | T20: young_mainstream | U20: 0 | AF20: suburban | AG20: 1 | AH20: 5.5 | AI20: 1.94 | AJ20: loam | AK20: semi_detached | AL20: 1870 | AM20: G | AN20: 0.717 | AO20: 873 | AQ20: 0 | AR20: 12 | AS20: 0 | AW20: 1 | AX20: 0 | AY20: 8 | AZ20: 2025 | BA20: single | BB20: posthub | BC20: true | BD20: email | BE20: INS14 | BF20: CMP12 | BG20: 3 | BH20: 2 | BI20: flat | BJ20: false | BK20: false | BL20: false | BM20: false | BN20: 9 | BO20: 7.1 | BP20: 50 | BQ20: 0.383 | BR20: 13.1 | BS20: 48843509 | BT20: A6557449
B21: M00176777 | C21: motor | D21: true | E21: broker | F21: 45661 | G21: 46022 | H21: 0.9918 | I21: 443.61 | J21: 25-34 | K21: 6 | L21: 5 | M21: 11 | N21: 5 | O21: comprehensive | P21: commuting | Q21: 0 | R21: annual | S21: 0 | T21: young_mainstream | U21: 1 | AF21: urban | AH21: 8.5 | AI21: 5.76 | AJ21: rock | AK21: semi_detached | AL21: 1875 | AM21: G | AN21: 0.81 | AO21: 1095 | AQ21: 0 | AR21: 23 | AS21: 0 | AW21: 1 | AX21: 3 | AZ21: 2025 | BA21: divorced | BB21: other | BC21: true | BD21: email | BE21: INS35 | BF21: CMP09 | BG21: 22 | BH21: 2 | BI21: pitched | BJ21: false | BK21: false | BL21: false | BM21: false | BN21: 10 | BO21: 4.4 | BP21: 44 | BQ21: 0.447 | BR21: 14.1 | BS21: 30215970 | BT21: A8460609
B22: M00185311 | C22: motor | D22: true | E22: direct | F22: 45671 | G22: 46022 | H22: 0.9644 | I22: 872.31 | J22: 17-24 | K22: 0 | L22: 1 | M22: 12 | O22: third_party_only | P22: business | Q22: 1000 | R22: monthly | S22: 0 | T22: young_affluent | U22: 0 | AF22: urban | AG22: 1 | AH22: 5.5 | AI22: 1.05 | AJ22: clay | AK22: terraced | AL22: 2017 | AM22: A | AN22: 0.652 | AO22: 1027 | AQ22: 0 | AR22: 26 | AS22: 0.05 | AW22: 1 | AX22: 0 | AY22: 7 | AZ22: 2025 | BA22: single | BB22: mailone | BC22: false | BD22: post | BE22: INS07 | BF22: CMP14 | BG22: 9 | BH22: 3 | BI22: pitched | BJ22: false | BK22: false | BL22: false | BM22: false | BN22: 13 | BO22: 6.8 | BP22: 13 | BQ22: 0.516 | BR22: 15.8 | BS22: 37533851 | BT22: A1367449
B23: B00215707 | C23: buildings | D23: true | E23: broker | F23: 45663 | G23: 46022 | H23: 0.9863 | I23: 272.44 | Q23: 0 | R23: monthly | S23: 0 | T23: mature_affluent | U23: 0 | V23: 50-64 | W23: 316000 | X23: BRK | AB23: true | AF23: urban | AG23: 1 | AH23: 12.5 | AI23: 5.8 | AJ23: chalk | AK23: detached | AL23: 2006 | AM23: B | AN23: 0.636 | AO23: 1196 | AP23: 9 | AQ23: 0 | AR23: 29 | AS23: 0 | AT23: owner_occupied | AU23: true | AV23: false | AW23: 4 | AX23: 0 | AY23: 14 | AZ23: 2025 | BA23: single | BB23: other | BC23: false | BD23: post | BE23: INS21 | BF23: CMP00 | BG23: 25 | BH23: 6 | BI23: pitched | BJ23: false | BK23: false | BL23: false | BM23: false | BN23: 16 | BO23: 6.7 | BP23: 36 | BQ23: 0.556 | BR23: 13.9 | BS23: 44849767 | BT23: A3936314
B24: B00215809 | C24: buildings | D24: true | E24: direct | F24: 45667 | G24: 46022 | H24: 0.9753 | I24: 237.22 | Q24: 0 | R24: annual | S24: 0 | T24: young_budget | U24: 0 | V24: 17-24 | W24: 362000 | X24: BRK | AB24: false | AF24: urban | AG24: 1 | AH24: 5.6 | AI24: 3.55 | AJ24: clay | AK24: detached | AL24: 1940 | AM24: F | AN24: 0.595 | AO24: 1369 | AP24: 6 | AQ24: 0 | AR24: 5 | AS24: 0.05 | AT24: owner_occupied | AV24: false | AW24: 2 | AX24: 0 | AY24: 5 | AZ24: 2025 | BB24: netbox | BC24: false | BD24: email | BE24: INS28 | BF24: CMP05 | BG24: 12 | BH24: 5 | BJ24: false | BK24: false | BL24: false | BM24: false | BN24: 7 | BO24: 3.4 | BP24: 7 | BQ24: 0.679 | BR24: 16.3 | BS24: 56272063 | BT24: A0629559
B25: B00217584 | C25: buildings | D25: true | E25: broker | F25: 45670 | G25: 46022 | H25: 0.9671 | I25: 323.36 | Q25: 0 | R25: monthly | S25: 0 | T25: mature_mainstream | U25: 0 | V25: 50-64 | W25: 198000 | X25: MIX | AB25: false | AF25: suburban | AH25: 0.6 | AI25: 1.66 | AJ25: sand | AK25: semi_detached | AL25: 1933 | AM25: D | AN25: 0.61 | AO25: 1639 | AQ25: 0 | AR25: 8 | AS25: 0 | AT25: owner_occupied | AU25: true | AV25: false | AW25: 5 | AX25: 0 | AY25: 17 | AZ25: 2025 | BA25: married | BB25: netbox | BC25: true | BD25: app | BE25: INS26 | BF25: CMP07 | BG25: 3 | BH25: 3 | BI25: pitched | BJ25: false | BK25: false | BL25: false | BM25: false | BN25: 13 | BO25: 1.9 | BP25: 26 | BQ25: 0.741 | BR25: 14.8 | BS25: 38298979 | BT25: A4959022
B26: B00218282 | C26: buildings | D26: true | E26: broker | F26: 45668 | G26: 46022 | H26: 0.9726 | I26: 230.8 | Q26: 250 | R26: annual | S26: 0 | T26: mature_affluent | U26: 1 | V26: 65+ | W26: 222000 | X26: MIX | AB26: false | AF26: rural | AG26: 1 | AH26: 10.9 | AI26: 2.16 | AJ26: rock | AK26: detached | AL26: 2020 | AM26: A | AN26: 0.992 | AO26: 1398 | AP26: 8 | AQ26: 0 | AR26: 0 | AS26: 0 | AT26: owner_occupied | AU26: true | AV26: false | AW26: 3 | AX26: 0 | AY26: 1 | AZ26: 2025 | BA26: married | BB26: other | BC26: true | BD26: email | BE26: INS25 | BF26: CMP08 | BG26: 25 | BH26: 3 | BI26: pitched | BJ26: false | BK26: false | BL26: false | BM26: false | BN26: 0 | BO26: 7.6 | BP26: 3 | BQ26: 0.739 | BR26: 19 | BS26: 44487130 | BT26: A6888229
B27: B00223369 | C27: buildings | D27: true | E27: broker | F27: 45660 | G27: 46022 | H27: 0.9945 | I27: 204.56 | Q27: 0 | R27: monthly | S27: 0 | T27: young_affluent | U27: 0 | V27: 17-24 | W27: 222000 | X27: WOD | AB27: false | AF27: suburban | AG27: 1 | AH27: 8.1 | AI27: 6.64 | AJ27: rock | AK27: semi_detached | AL27: 1903 | AM27: E | AN27: 0.577 | AO27: 1080 | AP27: 5 | AQ27: 0 | AR27: 9 | AS27: 0 | AT27: owner_occupied | AU27: true | AV27: true | AW27: 1 | AX27: 6 | AY27: 5 | AZ27: 2025 | BA27: single | BB27: inboxly | BC27: true | BD27: email | BE27: INS38 | BF27: CMP06 | BG27: 19 | BH27: 4 | BI27: pitched | BJ27: true | BK27: true | BL27: false | BM27: false | BN27: 12 | BO27: 7.8 | BP27: 5 | BQ27: 0.437 | BR27: 15.9 | BS27: 24183771 | BT27: A5001830
B28: B00229821 | C28: buildings | D28: true | E28: broker | F28: 45661 | G28: 46022 | H28: 0.9918 | I28: 285.6 | Q28: 250 | R28: monthly | S28: 0 | T28: mature_mainstream | U28: 0 | V28: 50-64 | W28: 378000 | X28: BRK | AB28: false | AF28: rural | AG28: 1 | AH28: 16 | AI28: 2.39 | AJ28: sand | AK28: terraced | AL28: 1979 | AM28: C | AN28: 0.571 | AO28: 1158 | AP28: 3 | AQ28: 0 | AR28: 21 | AS28: 0 | AT28: owner_occupied | AU28: true | AV28: true | AW28: 1 | AX28: 0 | AY28: 9 | AZ28: 2025 | BA28: single | BB28: other | BC28: true | BD28: email | BE28: INS16 | BF28: CMP06 | BG28: 10 | BH28: 4 | BI28: pitched | BJ28: false | BK28: false | BL28: false | BM28: false | BN28: 7 | BO28: 5.4 | BP28: 30 | BQ28: 0.53 | BR28: 14 | BS28: 32030141 | BT28: A4529319
B29: B00250679 | C29: buildings | D29: true | E29: broker | F29: 45983 | G29: 46022 | H29: 0.1096 | I29: 180.72 | Q29: 0 | R29: annual | S29: 0 | T29: midlife_budget | U29: 0 | V29: 35-49 | W29: 236000 | X29: BRK | AB29: true | AF29: rural | AG29: 1 | AH29: 3.2 | AI29: 9.41 | AJ29: clay | AK29: flat | AL29: 2013 | AM29: A | AN29: 0.852 | AO29: 1041 | AP29: 4 | AQ29: 0 | AR29: 20 | AS29: 0 | AT29: let | AU29: false | AV29: true | AW29: 4 | AX29: 0 | AY29: 4 | AZ29: 2025 | BA29: married | BB29: other | BC29: false | BD29: email | BE29: INS39 | BF29: CMP14 | BG29: 12 | BH29: 2 | BI29: flat | BJ29: false | BK29: false | BL29: false | BM29: true | BN29: 19 | BO29: 5.2 | BP29: 44 | BQ29: 0.395 | BR29: 14.4 | BS29: 61828611 | BT29: A3204800
B30: C00259568 | C30: contents | D30: false | E30: broker | F30: 45658 | G30: 46022 | H30: 1 | I30: 83.18 | Q30: 1000 | R30: monthly | S30: 0 | T30: young_affluent | U30: 0 | V30: 25-34 | W30: 22100 | Y30: renter | Z30: alarm_and_locks | AA30: 3 | AB30: false | AC30: false | AD30: false | AE30: false | AF30: suburban | AG30: 1 | AH30: 15.1 | AI30: 4.48 | AJ30: clay | AK30: semi_detached | AL30: 1987 | AM30: C | AN30: 0.515 | AO30: 1911 | AQ30: 14 | AR30: 13 | AS30: 0 | AW30: 3 | AX30: 0 | AY30: 3 | AZ30: 2011 | BA30: single | BB30: netbox | BC30: true | BD30: email | BE30: INS16 | BG30: 3 | BH30: 4 | BI30: pitched | BJ30: false | BK30: false | BL30: false | BM30: true | BN30: 17 | BO30: 3.7 | BP30: 14 | BQ30: 0.797 | BR30: 15.2 | BS30: 92249376 | BT30: A4488430
B31: C00270331 | C31: contents | D31: true | E31: broker | F31: 45668 | G31: 46022 | H31: 0.9726 | I31: 140.29 | Q31: 1000 | R31: annual | S31: 0 | T31: mature_mainstream | U31: 0 | V31: 50-64 | W31: 33400 | Y31: renter | Z31: alarm_and_locks | AB31: true | AC31: false | AD31: true | AE31: false | AF31: suburban | AG31: 1 | AH31: 17.1 | AI31: 1.86 | AJ31: loam | AK31: detached | AL31: 1951 | AM31: C | AN31: 0.809 | AO31: 980 | AQ31: 0 | AR31: 22 | AS31: 0 | AW31: 5 | AX31: 0 | AY31: 6 | AZ31: 2025 | BA31: married | BB31: posthub | BC31: false | BD31: email | BE31: INS18 | BF31: CMP13 | BG31: 3 | BH31: 3 | BI31: pitched | BJ31: false | BK31: false | BL31: false | BM31: false | BN31: 6 | BO31: 5.2 | BP31: 57 | BQ31: 0.309 | BR31: 13.1 | BS31: 58944765 | BT31: A3143736
B32: C00283470 | C32: contents | D32: true | E32: broker | F32: 45668 | G32: 46022 | H32: 0.9726 | I32: 117.97 | Q32: 250 | R32: annual | S32: 0 | T32: senior_affluent | U32: 1 | V32: 65+ | W32: 35700 | Y32: owner | Z32: locks | AA32: 4 | AB32: false | AC32: false | AD32: true | AE32: false | AF32: rural | AG32: 1 | AH32: 17.3 | AI32: 2.94 | AJ32: rock | AK32: terraced | AL32: 1956 | AM32: C | AN32: 0.606 | AO32: 1106 | AQ32: 0 | AR32: 4 | AS32: 0 | AX32: 0 | AY32: 3 | AZ32: 2025 | BA32: married | BB32: other | BC32: false | BD32: email | BE32: INS14 | BF32: CMP05 | BG32: 24 | BH32: 4 | BI32: pitched | BJ32: false | BK32: true | BL32: false | BM32: false | BN32: 10 | BO32: 6.8 | BP32: 18 | BQ32: 0.586 | BR32: 15.1 | BS32: 93454577 | BT32: A2257901
B33: C00286287 | C33: contents | D33: true | E33: broker | F33: 45670 | G33: 46022 | H33: 0.9671 | I33: 269.23 | Q33: 0 | R33: annual | S33: 0 | T33: midlife_mainstream | U33: 0 | V33: 35-49 | W33: 71100 | Y33: owner | Z33: standard | AA33: 0 | AB33: false | AC33: false | AD33: false | AE33: false | AF33: suburban | AG33: 3 | AH33: 1.6 | AI33: 0.23 | AK33: flat | AL33: 1975 | AM33: C | AN33: 0.665 | AO33: 1554 | AQ33: 0 | AR33: 28 | AS33: 0 | AW33: 3 | AX33: 0 | AZ33: 2025 | BA33: single | BB33: netbox | BC33: true | BD33: app | BE33: INS17 | BF33: CMP14 | BG33: 22 | BH33: 1 | BI33: pitched | BJ33: false | BK33: true | BL33: false | BM33: false | BN33: 5 | BO33: 2.4 | BP33: 27 | BQ33: 0.818 | BR33: 15.1 | BS33: 68661780 | BT33: A2307133
B34: C00302985 | C34: contents | D34: true | E34: broker | F34: 45661 | G34: 46022 | H34: 0.9918 | I34: 115.88 | Q34: 250 | R34: annual | S34: 0 | T34: senior_budget | U34: 0 | V34: 65+ | W34: 22900 | Y34: owner | Z34: alarm_and_locks | AA34: 5 | AB34: false | AC34: false | AD34: false | AE34: false | AF34: suburban | AG34: 1 | AH34: 32.4 | AI34: 5.58 | AJ34: clay | AK34: flat | AL34: 1900 | AM34: E | AN34: 0.64 | AO34: 1471 | AQ34: 0 | AR34: 19 | AS34: 0 | AW34: 4 | AX34: 0 | AY34: 9 | AZ34: 2025 | BB34: other | BC34: true | BD34: email | BE34: INS34 | BF34: CMP12 | BG34: 15 | BH34: 1 | BI34: pitched | BJ34: false | BK34: false | BL34: false | BM34: false | BN34: 12 | BO34: 1.3 | BP34: 15 | BQ34: 0.76 | BR34: 15.9 | BS34: 77971827 | BT34: A0664702
B35: C00314425 | C35: contents | D35: true | E35: broker | F35: 45670 | G35: 45694 | H35: 0.0685 | I35: 102.87 | Q35: 250 | R35: annual | S35: 0 | T35: young_affluent | U35: 1 | V35: 25-34 | W35: 27200 | Y35: owner | Z35: standard | AA35: 0 | AB35: false | AC35: false | AD35: false | AE35: false | AF35: rural | AG35: 1 | AH35: 1.5 | AI35: 2.3 | AJ35: clay | AK35: terraced | AL35: 1936 | AM35: C | AN35: 0.467 | AO35: 1009 | AQ35: 0 | AR35: 28 | AS35: 0 | AW35: 3 | AX35: 0 | AY35: 6 | AZ35: 2025 | BA35: married | BB35: netbox | BC35: true | BD35: app | BE35: INS35 | BF35: CMP14 | BG35: 8 | BH35: 3 | BI35: pitched | BJ35: false | BK35: false | BL35: false | BM35: false | BN35: 9 | BO35: 5.9 | BP35: 41 | BQ35: 0.378 | BR35: 12.2 | BS35: 27597742 | BT35: A3128511

Sheet Lookups
B2: Lookups: the fitted model as rating tables (export terms.csv), plus the input maps
B3: Key = line|component|term|level (or the value at the curve's recorded precision). Log contribution is added to the linear predictor; Relativity = EXP of it. Infinite band edges are written as +/-1E+307.
B5: Rating terms (8,100 rows) | P5: Categorical remaps
B6: Key | C6: Line | D6: Component | E6: Term | F6: Kind | G6: Level | H6: Value | I6: Band lower | J6: Band upper | K6: Log contribution | L6: Relativity | M6: Note | N6: Line|component|term | P6: Key | Q6: Scores as
B7: buildings|large|(intercept)| | C7: buildings | D7: large | E7: (intercept) | F7: intercept | K7: 5.9293315 | L7: =IF(ISNUMBER(K7),EXP(K7),"") | N7: buildings|large|(intercept) | P7: contents|small|f_prior_claims|3 | Q7: OTHER
B8: buildings|large|soil_type|MISSING | C8: buildings | D8: large | E8: soil_type | F8: categorical | G8: MISSING | K8: 0 | L8: =IF(ISNUMBER(K8),EXP(K8),"") | M8: base level | N8: buildings|large|soil_type | P8: contents|small|f_missed_pay|3 | Q8: OTHER
B9: buildings|large|soil_type|chalk | C9: buildings | D9: large | E9: soil_type | F9: categorical | G9: chalk | K9: 0.24009212 | L9: =IF(ISNUMBER(K9),EXP(K9),"") | N9: buildings|large|soil_type
B10: buildings|large|soil_type|clay | C10: buildings | D10: large | E10: soil_type | F10: categorical | G10: clay | K10: -0.08814148 | L10: =IF(ISNUMBER(K10),EXP(K10),"") | N10: buildings|large|soil_type | P10: Construction codes (BRK/MIX/STN/WOD)
B11: buildings|large|soil_type|loam | C11: buildings | D11: large | E11: soil_type | F11: categorical | G11: loam | K11: 0.18966518 | L11: =IF(ISNUMBER(K11),EXP(K11),"") | N11: buildings|large|soil_type | P11: Code | Q11: Model level
B12: buildings|large|soil_type|rock | C12: buildings | D12: large | E12: soil_type | F12: categorical | G12: rock | K12: -0.15840931 | L12: =IF(ISNUMBER(K12),EXP(K12),"") | N12: buildings|large|soil_type | P12: BRK | Q12: brick
B13: buildings|large|soil_type|sand | C13: buildings | D13: large | E13: soil_type | F13: categorical | G13: sand | K13: 0.17894645 | L13: =IF(ISNUMBER(K13),EXP(K13),"") | N13: buildings|large|soil_type | P13: MIX | Q13: non_standard
B14: buildings|large|soil_type|(any other level) | C14: buildings | D14: large | E14: soil_type | F14: categorical | G14: (any other level) | K14: 0 | L14: =IF(ISNUMBER(K14),EXP(K14),"") | M14: a level the fit did not see (including MISSING where no row is listed) scores as the base level | N14: buildings|large|soil_type | P14: STN | Q14: stone
B15: buildings|large|construction_type|brick | C15: buildings | D15: large | E15: construction_type | F15: categorical | G15: brick | K15: 0 | L15: =IF(ISNUMBER(K15),EXP(K15),"") | M15: base level | N15: buildings|large|construction_type | P15: WOD | Q15: timber
B16: buildings|large|construction_type|non_standard | C16: buildings | D16: large | E16: construction_type | F16: categorical | G16: non_standard | K16: 0.38602951 | L16: =IF(ISNUMBER(K16),EXP(K16),"") | N16: buildings|large|construction_type
B17: buildings|large|construction_type|stone | C17: buildings | D17: large | E17: construction_type | F17: categorical | G17: stone | K17: 0.2826839 | L17: =IF(ISNUMBER(K17),EXP(K17),"") | N17: buildings|large|construction_type | P17: Year built 1900 placeholder fill (D-27)
B18: buildings|large|construction_type|timber | C18: buildings | D18: large | E18: construction_type | F18: categorical | G18: timber | K18: 0.13627558 | L18: =IF(ISNUMBER(K18),EXP(K18),"") | N18: buildings|large|construction_type | P18: Energy rating | Q18: Year built
B19: buildings|large|construction_type|(any other level) | C19: buildings | D19: large | E19: construction_type | F19: categorical | G19: (any other level) | K19: 0 | L19: =IF(ISNUMBER(K19),EXP(K19),"") | M19: a level the fit did not see (including MISSING where no row is listed) scores as the base level | N19: buildings|large|construction_type | P19: A | Q19: 2008
B20: buildings|large|flood_zone|q00 | C20: buildings | D20: large | E20: flood_zone | F20: band | G20: q00 | I20: -1e+307 | J20: 1 | K20: -0.43961743 | L20: =IF(ISNUMBER(K20),EXP(K20),"") | M20: lower < x <= upper | N20: buildings|large|flood_zone | P20: B | Q20: 1993
B21: buildings|large|flood_zone|q01 | C21: buildings | D21: large | E21: flood_zone | F21: band | G21: q01 | I21: 1 | J21: 2 | K21: -0.42625283 | L21: =IF(ISNUMBER(K21),EXP(K21),"") | M21: lower < x <= upper | N21: buildings|large|flood_zone | P21: C | Q21: 1972
B22: buildings|large|flood_zone|q02 | C22: buildings | D22: large | E22: flood_zone | F22: band | G22: q02 | I22: 2 | J22: 1e+307 | K22: -0.34641947 | L22: =IF(ISNUMBER(K22),EXP(K22),"") | M22: lower < x <= upper | N22: buildings|large|flood_zone | P22: D | Q22: 1951
B23: buildings|large|flood_zone|MISSING | C23: buildings | D23: large | E23: flood_zone | F23: band | G23: MISSING | K23: 0 | L23: =IF(ISNUMBER(K23),EXP(K23),"") | M23: x missing; base level | N23: buildings|large|flood_zone | P23: E | Q23: 1929
B24: buildings|large|sum_insured|44000 | C24: buildings | D24: large | E24: sum_insured | F24: spline value | H24: 44000 | K24: -2.1985792 | L24: =IF(ISNUMBER(K24),EXP(K24),"") | M24: every value from 44000 to 894000 in steps of 1000 | N24: buildings|large|sum_insured | P24: F | Q24: 1902
B25: buildings|large|sum_insured|45000 | C25: buildings | D25: large | E25: sum_insured | F25: spline value | H25: 45000 | K25: -2.189532 | L25: =IF(ISNUMBER(K25),EXP(K25),"") | M25: every value from 44000 to 894000 in steps of 1000 | N25: buildings|large|sum_insured | P25: G | Q25: 1880
B26: buildings|large|sum_insured|46000 | C26: buildings | D26: large | E26: sum_insured | F26: spline value | H26: 46000 | K26: -2.1802154 | L26: =IF(ISNUMBER(K26),EXP(K26),"") | M26: every value from 44000 to 894000 in steps of 1000 | N26: buildings|large|sum_insured | P26: missing | Q26: 1961
B27: buildings|large|sum_insured|47000 | C27: buildings | D27: large | E27: sum_insured | F27: spline value | H27: 47000 | K27: -2.1706327 | L27: =IF(ISNUMBER(K27),EXP(K27),"") | M27: every value from 44000 to 894000 in steps of 1000 | N27: buildings|large|sum_insured
B28: buildings|large|sum_insured|48000 | C28: buildings | D28: large | E28: sum_insured | F28: spline value | H28: 48000 | K28: -2.1607875 | L28: =IF(ISNUMBER(K28),EXP(K28),"") | M28: every value from 44000 to 894000 in steps of 1000 | N28: buildings|large|sum_insured | P28: Curve lookup precision
B29: buildings|large|sum_insured|49000 | C29: buildings | D29: large | E29: sum_insured | F29: spline value | H29: 49000 | K29: -2.1506832 | L29: =IF(ISNUMBER(K29),EXP(K29),"") | M29: every value from 44000 to 894000 in steps of 1000 | N29: buildings|large|sum_insured | P29: Line|component|term | Q29: Key format
B30: buildings|large|sum_insured|50000 | C30: buildings | D30: large | E30: sum_insured | F30: spline value | H30: 50000 | K30: -2.1403233 | L30: =IF(ISNUMBER(K30),EXP(K30),"") | M30: every value from 44000 to 894000 in steps of 1000 | N30: buildings|large|sum_insured | P30: buildings|large|distance_to_river_km | Q30: 0.00
B31: buildings|large|sum_insured|51000 | C31: buildings | D31: large | E31: sum_insured | F31: spline value | H31: 51000 | K31: -2.1297112 | L31: =IF(ISNUMBER(K31),EXP(K31),"") | M31: every value from 44000 to 894000 in steps of 1000 | N31: buildings|large|sum_insured | P31: buildings|large|elevation_m | Q31: 0.0
B32: buildings|large|sum_insured|52000 | C32: buildings | D32: large | E32: sum_insured | F32: spline value | H32: 52000 | K32: -2.1188504 | L32: =IF(ISNUMBER(K32),EXP(K32),"") | M32: every value from 44000 to 894000 in steps of 1000 | N32: buildings|large|sum_insured | P32: buildings|large|sum_insured | Q32: 0
B33: buildings|large|sum_insured|53000 | C33: buildings | D33: large | E33: sum_insured | F33: spline value | H33: 53000 | K33: -2.1077442 | L33: =IF(ISNUMBER(K33),EXP(K33),"") | M33: every value from 44000 to 894000 in steps of 1000 | N33: buildings|large|sum_insured | P33: buildings|large|year_built | Q33: 0
B34: buildings|large|sum_insured|54000 | C34: buildings | D34: large | E34: sum_insured | F34: spline value | H34: 54000 | K34: -2.0963963 | L34: =IF(ISNUMBER(K34),EXP(K34),"") | M34: every value from 44000 to 894000 in steps of 1000 | N34: buildings|large|sum_insured | P34: contents|small|distance_to_river_km | Q34: 0.00
B35: buildings|large|sum_insured|55000 | C35: buildings | D35: large | E35: sum_insured | F35: spline value | H35: 55000 | K35: -2.0848099 | L35: =IF(ISNUMBER(K35),EXP(K35),"") | M35: every value from 44000 to 894000 in steps of 1000 | N35: buildings|large|sum_insured | P35: contents|small|elevation_m | Q35: 0.0
B36: buildings|large|sum_insured|56000 | C36: buildings | D36: large | E36: sum_insured | F36: spline value | H36: 56000 | K36: -2.0729887 | L36: =IF(ISNUMBER(K36),EXP(K36),"") | M36: every value from 44000 to 894000 in steps of 1000 | N36: buildings|large|sum_insured | P36: motor|small|ncb_years | Q36: 0
B37: buildings|large|sum_insured|57000 | C37: buildings | D37: large | E37: sum_insured | F37: spline value | H37: 57000 | K37: -2.0609359 | L37: =IF(ISNUMBER(K37),EXP(K37),"") | M37: every value from 44000 to 894000 in steps of 1000 | N37: buildings|large|sum_insured | P37: motor|small|vehicle_age | Q37: 0
B38: buildings|large|sum_insured|58000 | C38: buildings | D38: large | E38: sum_insured | F38: spline value | H38: 58000 | K38: -2.0486552 | L38: =IF(ISNUMBER(K38),EXP(K38),"") | M38: every value from 44000 to 894000 in steps of 1000 | N38: buildings|large|sum_insured | P38: motor|small|vehicle_value_group | Q38: 0
B39: buildings|large|sum_insured|59000 | C39: buildings | D39: large | E39: sum_insured | F39: spline value | H39: 59000 | K39: -2.0361499 | L39: =IF(ISNUMBER(K39),EXP(K39),"") | M39: every value from 44000 to 894000 in steps of 1000 | N39: buildings|large|sum_insured | P39: motor|small|voluntary_excess | Q39: 0
B40: buildings|large|sum_insured|60000 | C40: buildings | D40: large | E40: sum_insured | F40: spline value | H40: 60000 | K40: -2.0234234 | L40: =IF(ISNUMBER(K40),EXP(K40),"") | M40: every value from 44000 to 894000 in steps of 1000 | N40: buildings|large|sum_insured | P40: motor|small|years_licensed | Q40: 0
B41: buildings|large|sum_insured|61000 | C41: buildings | D41: large | E41: sum_insured | F41: spline value | H41: 61000 | K41: -2.0104793 | L41: =IF(ISNUMBER(K41),EXP(K41),"") | M41: every value from 44000 to 894000 in steps of 1000 | N41: buildings|large|sum_insured
B42: buildings|large|sum_insured|62000 | C42: buildings | D42: large | E42: sum_insured | F42: spline value | H42: 62000 | K42: -1.997321 | L42: =IF(ISNUMBER(K42),EXP(K42),"") | M42: every value from 44000 to 894000 in steps of 1000 | N42: buildings|large|sum_insured
...

Sheet Lookups Trees
B2: Lookups Trees: the buildings small-claim XGBoost as tables (export buildings_xgboost_nodes.csv and _features.csv)
B3: Walk each tree from node 0: split -> left if x < Threshold, else right; category split -> right if the input's code is in Right codes, else left; a missing input goes to Missing goes; at a leaf take Leaf value. One leaf per tree, 193 trees.
B5: Tree nodes (2,577 rows) | P5: Features and category codes (218 rows)
B6: Key | C6: Tree | D6: Node | E6: Kind | F6: Position | G6: Feature | H6: Threshold | I6: Right codes | J6: Right levels | K6: Missing goes | L6: Left | M6: Right | N6: Leaf value | P6: Key | Q6: Position | R6: Feature | S6: Type | T6: Code | U6: Level | V6: Note
B7: 0|0 | C7: 0 | D7: 0 | E7: split | F7: 12 | G7: flood_zone | H7: 3.9999999 | K7: right | L7: 1 | M7: 2 | P7: sum_insured| | Q7: 0 | R7: sum_insured | S7: numeric | V7: after D-02 (divided by 1,000 at 10m or more)
B8: 0|1 | C8: 0 | D8: 1 | E8: split | F8: 15 | G8: year_built | H8: 1943.9999 | K8: right | L8: 3 | M8: 4 | P8: days_unoccupied| | Q8: 1 | R8: days_unoccupied | S8: numeric
B9: 0|2 | C9: 0 | D9: 2 | E9: split | F9: 14 | G9: elevation_m | H9: 2.1999999 | K9: right | L9: 5 | M9: 6 | P9: voluntary_excess| | Q9: 2 | R9: voluntary_excess | S9: numeric
B10: 0|3 | C10: 0 | D10: 3 | E10: split | F10: 16 | G10: bedrooms | H10: 1.9999999 | K10: right | L10: 7 | M10: 8 | P10: missed_payments_12m| | Q10: 3 | R10: missed_payments_12m | S10: numeric
B11: 0|4 | C11: 0 | D11: 4 | E11: split | F11: 16 | G11: bedrooms | H11: 2.9999999 | K11: right | L11: 9 | M11: 10 | P11: renewal_count| | Q11: 4 | R11: renewal_count | S11: numeric
B12: 0|5 | C12: 0 | D12: 5 | E12: split | F12: 12 | G12: flood_zone | H12: 4.9999998 | K12: left | L12: 11 | M12: 12 | P12: days_quote_to_inception| | Q12: 5 | R12: days_quote_to_inception | S12: numeric
B13: 0|6 | C13: 0 | D13: 6 | E13: split | F13: 13 | G13: distance_to_river_km | H13: 0.46999998 | K13: left | L13: 13 | M13: 14 | P13: discount_applied| | Q13: 6 | R13: discount_applied | S13: numeric
B14: 0|7 | C14: 0 | D14: 7 | E14: leaf | N14: -0.026052235 | P14: household_size| | Q14: 7 | R14: household_size | S14: numeric
B15: 0|8 | C15: 0 | D15: 8 | E15: leaf | N15: 0.0063153445 | P15: prior_claims_5y| | Q15: 8 | R15: prior_claims_5y | S15: numeric
B16: 0|9 | C16: 0 | D16: 9 | E16: leaf | N16: -0.030850871 | P16: licence_points| | Q16: 9 | R16: licence_points | S16: numeric
B17: 0|10 | C17: 0 | D17: 10 | E17: leaf | N17: -0.014001446 | P17: years_at_address| | Q17: 10 | R17: years_at_address | S17: numeric
B18: 0|11 | C18: 0 | D18: 11 | E18: leaf | N18: 0.050961323 | P18: customer_since_year| | Q18: 11 | R18: customer_since_year | S18: numeric
B19: 0|12 | C19: 0 | D19: 12 | E19: leaf | N19: 0.072398752 | P19: flood_zone| | Q19: 12 | R19: flood_zone | S19: numeric
B20: 0|13 | C20: 0 | D20: 13 | E20: leaf | N20: 0.027706048 | P20: distance_to_river_km| | Q20: 13 | R20: distance_to_river_km | S20: numeric
B21: 0|14 | C21: 0 | D21: 14 | E21: leaf | N21: 0.00059787929 | P21: elevation_m| | Q21: 14 | R21: elevation_m | S21: numeric
B22: 1|0 | C22: 1 | D22: 0 | E22: split | F22: 25 | G22: x_fz3_rain | H22: 0.71399996 | K22: right | L22: 1 | M22: 2 | P22: year_built| | Q22: 15 | R22: year_built | S22: numeric
B23: 1|1 | C23: 1 | D23: 1 | E23: split | F23: 15 | G23: year_built | H23: 1943.9999 | K23: right | L23: 3 | M23: 4 | P23: bedrooms| | Q23: 16 | R23: bedrooms | S23: numeric
B24: 1|2 | C24: 1 | D24: 2 | E24: split | F24: 13 | G24: distance_to_river_km | H24: 0.49999999 | K24: left | L24: 5 | M24: 6 | P24: hail_days| | Q24: 17 | R24: hail_days | S24: numeric
B25: 1|3 | C25: 1 | D25: 3 | E25: split | F25: 0 | G25: sum_insured | H25: 204999.99 | K25: right | L25: 7 | M25: 8 | P25: wind_exposure_index| | Q25: 18 | R25: wind_exposure_index | S25: numeric
B26: 1|4 | C26: 1 | D26: 4 | E26: split | F26: 0 | G26: sum_insured | H26: 206999.99 | K26: right | L26: 9 | M26: 10 | P26: freezing_days| | Q26: 19 | R26: freezing_days | S26: numeric
B27: 1|5 | C27: 1 | D27: 5 | E27: split | F27: 0 | G27: sum_insured | H27: 231999.99 | K27: right | L27: 11 | M27: 12 | P27: dry_summer_index| | Q27: 20 | R27: dry_summer_index | S27: numeric
B28: 1|6 | C28: 1 | D28: 6 | E28: split | F28: 13 | G28: distance_to_river_km | H28: 0.86999997 | K28: right | L28: 13 | M28: 14 | P28: wildfire_index| | Q28: 21 | R28: wildfire_index | S28: numeric
B29: 1|7 | C29: 1 | D29: 7 | E29: leaf | N29: -0.011357153 | P29: rainfall_mm| | Q29: 22 | R29: rainfall_mm | S29: numeric
B30: 1|8 | C30: 1 | D30: 8 | E30: leaf | N30: 0.010176425 | P30: mean_temperature_c| | Q30: 23 | R30: mean_temperature_c | S30: numeric
B31: 1|9 | C31: 1 | D31: 9 | E31: leaf | N31: -0.032427829 | P31: x_clay_dry| | Q31: 24 | R31: x_clay_dry | S31: numeric | V31: coalesce((soil_type = 'clay') x dry_summer_index, 0) (sql/11, A28)
B32: 1|10 | C32: 1 | D32: 10 | E32: leaf | N32: -0.012212122 | P32: x_fz3_rain| | Q32: 25 | R32: x_fz3_rain | S32: numeric | V32: coalesce((coalesce(flood_zone, 99) >= 3) x rainfall_mm / 1000, 0): a missing flood zone counts as 3 or above (sql/11, A28)
B33: 1|11 | C33: 1 | D33: 11 | E33: leaf | N33: 0.035709471 | P33: construction_type|brick | Q33: 26 | R33: construction_type | S33: categorical | T33: 0 | U33: brick
B34: 1|12 | C34: 1 | D34: 12 | E34: leaf | N34: 0.05500263 | P34: construction_type|non_standard | Q34: 26 | R34: construction_type | S34: categorical | T34: 1 | U34: non_standard
B35: 1|13 | C35: 1 | D35: 13 | E35: leaf | N35: 0.025253523 | P35: construction_type|stone | Q35: 26 | R35: construction_type | S35: categorical | T35: 2 | U35: stone
B36: 1|14 | C36: 1 | D36: 14 | E36: leaf | N36: 0.0046834233 | P36: construction_type|timber | Q36: 26 | R36: construction_type | S36: categorical | T36: 3 | U36: timber
B37: 2|0 | C37: 2 | D37: 0 | E37: split | F37: 12 | G37: flood_zone | H37: 3.9999999 | K37: right | L37: 1 | M37: 2 | P37: construction_type|(any other level) | Q37: 26 | R37: construction_type | S37: categorical | U37: (any other level) | V37: no code: missing, so each split's default branch
B38: 2|1 | C38: 2 | D38: 1 | E38: split | F38: 0 | G38: sum_insured | H38: 208999.99 | K38: right | L38: 3 | M38: 4 | P38: occupancy|let | Q38: 27 | R38: occupancy | S38: categorical | T38: 0 | U38: let
B39: 2|2 | C39: 2 | D39: 2 | E39: split | F39: 14 | G39: elevation_m | H39: 2.1999999 | K39: right | L39: 5 | M39: 6 | P39: occupancy|owner_occupied | Q39: 27 | R39: occupancy | S39: categorical | T39: 1 | U39: owner_occupied
B40: 2|3 | C40: 2 | D40: 3 | E40: category split | F40: 49 | G40: energy_rating | I40: 0;1;2;3 | J40: A;B;C;D | K40: left | L40: 7 | M40: 8 | P40: occupancy|(any other level) | Q40: 27 | R40: occupancy | S40: categorical | U40: (any other level) | V40: no code: missing, so each split's default branch
B41: 2|4 | C41: 2 | D41: 4 | E41: category split | F41: 49 | G41: energy_rating | I41: 0;1;2;3 | J41: A;B;C;D | K41: left | L41: 9 | M41: 10 | P41: smoke_alarms|False | Q41: 28 | R41: smoke_alarms | S41: categorical | T41: 0 | U41: False
B42: 2|5 | C42: 2 | D42: 5 | E42: split | F42: 12 | G42: flood_zone | H42: 4.9999998 | K42: left | L42: 11 | M42: 12 | P42: smoke_alarms|MISSING | Q42: 28 | R42: smoke_alarms | S42: categorical | T42: 1 | U42: MISSING
...

Sheet Rating Motor
B2: Rating Motor: small-claim GLM + large-claim GLM, then the level steps
B3: Each term: the key it looks up (line|component|term|level) and its log contribution. Row 8 holds the term's key prefix. Prediction = EXP(sum of logs) per component.
BR4: Rows off Python (0 = pass) | BS4: Keys not found (0 = pass)
B5: Checks sit above their own columns at the right. | BR5: =COUNTIF(BR10:BR16,">1E-9") | BS5: =SUM(BS10:BS16)
B7: Policy | G7: Inputs | U7: Small claims GLM | BB7: Large claims GLM | BN7: Prediction | BQ7: Check against Python
U8: motor|small|marketing_segment | W8: motor|small|cover_type | Y8: motor|small|urban_density | AA8: motor|small|channel | AC8: motor|small|vehicle_use | AE8: motor|small|payment_method | AG8: motor|small|driver_age_band | AI8: motor|small|prior_claims_5y | AK8: motor|small|missed_payments_12m | AM8: motor|small|ncb_years | AO8: motor|small|years_licensed | AQ8: motor|small|vehicle_age | AS8: motor|small|vehicle_value_group | AU8: motor|small|voluntary_excess | AW8: motor|small|(intercept)| | AX8: motor|small|trend|log contribution in 2025 | BB8: motor|large|driver_age_band | BD8: motor|large|ncb_years | BF8: motor|large|years_licensed | BH8: motor|large|(intercept)| | BI8: motor|large|trend|log contribution in 2025 | BK8: motor|large|Pareto adjustment|
B9: Policy row | C9: New business | D9: Period start | E9: Period end | F9: Exposure (model, D-01) | G9: marketing_segment | H9: cover_type | I9: urban_density | J9: channel | K9: vehicle_use | L9: payment_method | M9: driver_age_band | N9: prior_claims_5y | O9: missed_payments_12m | P9: ncb_years | Q9: years_licensed | R9: vehicle_age | S9: vehicle_value_group | T9: voluntary_excess | U9: marketing_segment: key | V9: marketing_segment: log | W9: cover_type: key | X9: cover_type: log | Y9: urban_density: key | Z9: urban_density: log | AA9: channel: key | AB9: channel: log | AC9: vehicle_use: key | AD9: vehicle_use: log | AE9: payment_method: key | AF9: payment_method: log | AG9: driver_age_band: key | AH9: driver_age_band: log | AI9: prior_claims_5y: band | AJ9: prior_claims_5y: log | AK9: missed_payments_12m: band | AL9: missed_payments_12m: log | AM9: ncb_years: key | AN9: ncb_years: log | AO9: years_licensed: key | AP9: years_licensed: log | AQ9: vehicle_age: key | AR9: vehicle_age: log | AS9: vehicle_value_group: key | AT9: vehicle_value_group: log | AU9: voluntary_excess: key | AV9: voluntary_excess: log | AW9: Intercept | AX9: Trend to 2025 | AY9: ln(exposure) | AZ9: Log prediction | BA9: Small claim (CU) | BB9: driver_age_band: key | BC9: driver_age_band: log | BD9: ncb_years: band | BE9: ncb_years: log | BF9: years_licensed: band | BG9: years_licensed: log | BH9: Intercept | BI9: Trend to 2025 | BJ9: ln(exposure) | BK9: ln(Pareto adj.) | BL9: Log prediction | BM9: Large claim (CU) | BN9: As is (CU) | BO9: Level step 1 | BP9: Final risk premium (CU) | BQ9: Python final | BR9: Relative difference | BS9: Keys not found
B10: ='Int. Inputs'!$B$16 | C10: =IF(ISBLANK(INDEX(Pol_Data,MATCH($B10,Pol_ID,0),MATCH("new_business",Pol_Head,0))),"",INDEX(Pol_Data,MATCH($B10,Pol_ID,0),MATCH("new_business",Pol_Head,0))) | D10: =IF(ISBLANK(INDEX(Pol_Data,MATCH($B10,Pol_ID,0),MATCH("period_start",Pol_Head,0))),"",INDEX(Pol_Data,MATCH($B10,Pol_ID,0),MATCH("period_start",Pol_Head,0))) | E10: =IF(ISBLANK(INDEX(Pol_Data,MATCH($B10,Pol_ID,0),MATCH("period_end",Pol_Head,0))),"",INDEX(Pol_Data,MATCH($B10,Pol_ID,0),MATCH("period_end",Pol_Head,0))) | F10: =(E10-D10+1)/365 | G10: =IF(ISBLANK(INDEX(Pol_Data,MATCH($B10,Pol_ID,0),MATCH("marketing_segment",Pol_Head,0))),"",INDEX(Pol_Data,MATCH($B10,Pol_ID,0),MATCH("marketing_segment",Pol_Head,0))) | H10: =IF(ISBLANK(INDEX(Pol_Data,MATCH($B10,Pol_ID,0),MATCH("cover_type",Pol_Head,0))),"",INDEX(Pol_Data,MATCH($B10,Pol_ID,0),MATCH("cover_type",Pol_Head,0))) | I10: =IF(ISBLANK(INDEX(Pol_Data,MATCH($B10,Pol_ID,0),MATCH("urban_density",Pol_Head,0))),"",INDEX(Pol_Data,MATCH($B10,Pol_ID,0),MATCH("urban_density",Pol_Head,0))) | J10: =IF(ISBLANK(INDEX(Pol_Data,MATCH($B10,Pol_ID,0),MATCH("channel",Pol_Head,0))),"",INDEX(Pol_Data,MATCH($B10,Pol_ID,0),MATCH("channel",Pol_Head,0))) | K10: =IF(ISBLANK(INDEX(Pol_Data,MATCH($B10,Pol_ID,0),MATCH("vehicle_use",Pol_Head,0))),"",INDEX(Pol_Data,MATCH($B10,Pol_ID,0),MATCH("vehicle_use",Pol_Head,0))) | L10: =IF(ISBLANK(INDEX(Pol_Data,MATCH($B10,Pol_ID,0),MATCH("payment_method",Pol_Head,0))),"",INDEX(Pol_Data,MATCH($B10,Pol_ID,0),MATCH("payment_method",Pol_Head,0))) | M10: =IF(ISBLANK(INDEX(Pol_Data,MATCH($B10,Pol_ID,0),MATCH("driver_age_band",Pol_Head,0))),"",INDEX(Pol_Data,MATCH($B10,Pol_ID,0),MATCH("driver_age_band",Pol_Head,0))) | N10: =IF(ISBLANK(INDEX(Pol_Data,MATCH($B10,Pol_ID,0),MATCH("prior_claims_5y",Pol_Head,0))),"",INDEX(Pol_Data,MATCH($B10,Pol_ID,0),MATCH("prior_claims_5y",Pol_Head,0))) | O10: =IF(ISBLANK(INDEX(Pol_Data,MATCH($B10,Pol_ID,0),MATCH("missed_payments_12m",Pol_Head,0))),"",INDEX(Pol_Data,MATCH($B10,Pol_ID,0),MATCH("missed_payments_12m",Pol_Head,0))) | P10: =IF(ISBLANK(INDEX(Pol_Data,MATCH($B10,Pol_ID,0),MATCH("ncb_years",Pol_Head,0))),"",INDEX(Pol_Data,MATCH($B10,Pol_ID,0),MATCH("ncb_years",Pol_Head,0))) | Q10: =IF(ISBLANK(INDEX(Pol_Data,MATCH($B10,Pol_ID,0),MATCH("years_licensed",Pol_Head,0))),"",INDEX(Pol_Data,MATCH($B10,Pol_ID,0),MATCH("years_licensed",Pol_Head,0))) | R10: =IF(ISBLANK(INDEX(Pol_Data,MATCH($B10,Pol_ID,0),MATCH("vehicle_age",Pol_Head,0))),"",INDEX(Pol_Data,MATCH($B10,Pol_ID,0),MATCH("vehicle_age",Pol_Head,0))) | S10: =IF(ISBLANK(INDEX(Pol_Data,MATCH($B10,Pol_ID,0),MATCH("vehicle_value_group",Pol_Head,0))),"",INDEX(Pol_Data,MATCH($B10,Pol_ID,0),MATCH("vehicle_value_group",Pol_Head,0))) | T10: =IF(ISBLANK(INDEX(Pol_Data,MATCH($B10,Pol_ID,0),MATCH("voluntary_excess",Pol_Head,0))),"",INDEX(Pol_Data,MATCH($B10,Pol_ID,0),MATCH("voluntary_excess",Pol_Head,0))) | U10: =IFERROR(INDEX(Remap_To,MATCH(U$8&"|"&IF(G10="","MISSING",G10&""),Remap_Key,0)),U$8&"|"&IF(G10="","MISSING",G10&"")) | V10: =IFERROR(INDEX(Terms_Contrib,MATCH(U10,Terms_Key,0)),0) | W10: =IFERROR(INDEX(Remap_To,MATCH(W$8&"|"&IF(H10="","MISSING",H10&""),Remap_Key,0)),W$8&"|"&IF(H10="","MISSING",H10&"")) | X10: =IFERROR(INDEX(Terms_Contrib,MATCH(W10,Terms_Key,0)),0) | Y10: =IFERROR(INDEX(Remap_To,MATCH(Y$8&"|"&IF(I10="","MISSING",I10&""),Remap_Key,0)),Y$8&"|"&IF(I10="","MISSING",I10&"")) | Z10: =IFERROR(INDEX(Terms_Contrib,MATCH(Y10,Terms_Key,0)),0) | AA10: =IFERROR(INDEX(Remap_To,MATCH(AA$8&"|"&IF(J10="","MISSING",J10&""),Remap_Key,0)),AA$8&"|"&IF(J10="","MISSING",J10&"")) | AB10: =IFERROR(INDEX(Terms_Contrib,MATCH(AA10,Terms_Key,0)),0) | AC10: =IFERROR(INDEX(Remap_To,MATCH(AC$8&"|"&IF(K10="","MISSING",K10&""),Remap_Key,0)),AC$8&"|"&IF(K10="","MISSING",K10&"")) | AD10: =IFERROR(INDEX(Terms_Contrib,MATCH(AC10,Terms_Key,0)),0) | AE10: =IFERROR(INDEX(Remap_To,MATCH(AE$8&"|"&IF(L10="","MISSING",L10&""),Remap_Key,0)),AE$8&"|"&IF(L10="","MISSING",L10&"")) | AF10: =IFERROR(INDEX(Terms_Contrib,MATCH(AE10,Terms_Key,0)),0) | AG10: =IFERROR(INDEX(Remap_To,MATCH(AG$8&"|"&IF(M10="","MISSING",M10&""),Remap_Key,0)),AG$8&"|"&IF(M10="","MISSING",M10&"")) | AH10: =IFERROR(INDEX(Terms_Contrib,MATCH(AG10,Terms_Key,0)),0) | AI10: =IF(N10="",AI$8&"|MISSING",AI$8&"|q"&TEXT(COUNTIFS(Terms_LCT,AI$8,Terms_Kind,"band",Terms_Lower,"<"&N10)-1,"00")) | AJ10: =IFERROR(INDEX(Terms_Contrib,MATCH(AI10,Terms_Key,0)),0) | AK10: =IF(O10="",AK$8&"|MISSING",AK$8&"|q"&TEXT(COUNTIFS(Terms_LCT,AK$8,Terms_Kind,"band",Terms_Lower,"<"&O10)-1,"00")) | AL10: =IFERROR(INDEX(Terms_Contrib,MATCH(AK10,Terms_Key,0)),0) | AM10: =IF(P10="",AM$8&"|MISSING",AM$8&"|"&TEXT(P10,INDEX(Fmt_Str,MATCH(AM$8,Fmt_LCT,0)))) | AN10: =IFERROR(INDEX(Terms_Contrib,MATCH(AM10,Terms_Key,0)),0) | AO10: =IF(Q10="",AO$8&"|MISSING",AO$8&"|"&TEXT(Q10,INDEX(Fmt_Str,MATCH(AO$8,Fmt_LCT,0)))) | AP10: =IFERROR(INDEX(Terms_Contrib,MATCH(AO10,Terms_Key,0)),0) | AQ10: =IF(R10="",AQ$8&"|MISSING",AQ$8&"|"&TEXT(R10,INDEX(Fmt_Str,MATCH(AQ$8,Fmt_LCT,0)))) | AR10: =IFERROR(INDEX(Terms_Contrib,MATCH(AQ10,Terms_Key,0)),0) | AS10: =IF(S10="",AS$8&"|MISSING",AS$8&"|"&TEXT(S10,INDEX(Fmt_Str,MATCH(AS$8,Fmt_LCT,0)))) | AT10: =IFERROR(INDEX(Terms_Contrib,MATCH(AS10,Terms_Key,0)),0) | AU10: =IF(T10="",AU$8&"|MISSING",AU$8&"|"&TEXT(T10,INDEX(Fmt_Str,MATCH(AU$8,Fmt_LCT,0)))) | AV10: =IFERROR(INDEX(Terms_Contrib,MATCH(AU10,Terms_Key,0)),0) | AW10: =INDEX(Terms_Contrib,MATCH(AW$8,Terms_Key,0)) | AX10: =INDEX(Terms_Contrib,MATCH(AX$8,Terms_Key,0)) | AY10: =LN(F10) | AZ10: =V10+X10+Z10+AB10+AD10+AF10+AH10+AJ10+AL10+AN10+AP10+AR10+AT10+AV10+AW10+AX10+AY10 | BA10: =EXP(AZ10) | BB10: =IFERROR(INDEX(Remap_To,MATCH(BB$8&"|"&IF(M10="","MISSING",M10&""),Remap_Key,0)),BB$8&"|"&IF(M10="","MISSING",M10&"")) | BC10: =IFERROR(INDEX(Terms_Contrib,MATCH(BB10,Terms_Key,0)),0) | BD10: =IF(P10="",BD$8&"|MISSING",BD$8&"|q"&TEXT(COUNTIFS(Terms_LCT,BD$8,Terms_Kind,"band",Terms_Lower,"<"&P10)-1,"00")) | BE10: =IFERROR(INDEX(Terms_Contrib,MATCH(BD10,Terms_Key,0)),0) | BF10: =IF(Q10="",BF$8&"|MISSING",BF$8&"|q"&TEXT(COUNTIFS(Terms_LCT,BF$8,Terms_Kind,"band",Terms_Lower,"<"&Q10)-1,"00")) | BG10: =IFERROR(INDEX(Terms_Contrib,MATCH(BF10,Terms_Key,0)),0) | BH10: =INDEX(Terms_Contrib,MATCH(BH$8,Terms_Key,0)) | BI10: =INDEX(Terms_Contrib,MATCH(BI$8,Terms_Key,0)) | BJ10: =LN(F10) | BK10: =INDEX(Terms_Contrib,MATCH(BK$8,Terms_Key,0)) | BL10: =BC10+BE10+BG10+BH10+BI10+BJ10+BK10 | BM10: =EXP(BL10) | BN10: =BA10+BM10 | BO10: =IF(C10="true",Lvl_MotNB,Lvl_MotRen) | BP10: =IF(C10="true",BN10*BO10*Lvl_MotNB2/BO10,BN10*BO10) | BQ10: =INDEX(Py_Final,MATCH($B10,Py_ID,0)) | BR10: =ABS(BP10/BQ10-1) | BS10: =ISNA(MATCH(U10,Terms_Key,0))+ISNA(MATCH(W10,Terms_Key,0))+ISNA(MATCH(Y10,Terms_Key,0))+ISNA(MATCH(AA10,Terms_Key,0))+ISNA(MATCH(AC10,Terms_Key,0))+ISNA(MATCH(AE10,Terms_Key,0))+ISNA(MATCH(AG10,Terms_Key,0))+ISNA(MATCH(AI10,Terms_Key,0))+ISNA(MATCH(AK10,Terms_Key,0))+ISNA(MATCH(AM10,Terms_Key,0))+ISNA(MATCH(AO10,Terms_Key,0))+ISNA(MATCH(AQ10,Terms_Key,0))+ISNA(MATCH(AS10,Terms_Key,0))+ISNA(MATCH(AU10,Terms_Key,0))+ISNA(MATCH(AW$8,Terms_Key,0))+ISNA(MATCH(AX$8,Terms_Key,0))+ISNA(MATCH(BB10,Terms_Key,0))+ISNA(MATCH(BD10,Terms_Key,0))+ISNA(MATCH(BF10,Terms_Key,0))+ISNA(MATCH(BH$8,Terms_Key,0))+ISNA(MATCH(BI$8,Terms_Key,0))+ISNA(MATCH(BK$8,Terms_Key,0))
